Workbook

Sheet Assumptions
A1: Decibyl financial model, assumptions
A2: Blue cells with yellow fill are inputs. Every other sheet computes from here. Dated 14 Sept 2026; sources in column D.
A4: LEGEND
A5: Input, edit me
A6: Formula, do not edit
A7: Link from another sheet
A9: General
A10: INR per USD | B10: 96 | D10: data/pricing.ts USD_RATE
A11: Value of one credit, ₹ | B11: 0.5 | D11: Pricing decision, 14 Sept: 1 credit = ₹0.50 of composed cost
A12: Opening cash, ₹ | B12: 500000 | D12: ROADMAP.md: about ₹5L runway. Founder-stated
A13: Payment fee, % of revenue | B13: 0.024 | D13: Razorpay 2% + GST; baked into price
A14: Months modelled | B14: 24 | D14: Fixed at 24 in the Model sheet
A15: Plans: price, credits, usage
A16: Everyday: price ₹/month | B16: 999 | D16: As shipped 14 Sept: subscription_plans.py LADDER_SEED
A17: Everyday: credits per month | B17: 2000
A18: Everyday: share of plan credits actually used | B18: 0.6 | D18: Assumption; measure from the ledger after month 2
A19: Everyday: top-up and overage revenue, % of plan price | B19: 0 | D19: Assumption; voice plans buy top-ups, text plan does not
A20: Everyday: share of used credits spent on voice | B20: 0 | D20: Everyday has no voice by design
A21: Everyday: monthly churn | B21: 0.08 | D21: Assumption; Indian SMB SaaS benchmarks 3 to 8%
A22: Everyday: phone numbers included | B22: 0 | D22: Pricing ladder
A23: Business: price ₹/month | B23: 2999 | D23: As shipped 14 Sept: subscription_plans.py LADDER_SEED
A24: Business: credits per month | B24: 6000
A25: Business: share of plan credits actually used | B25: 0.7 | D25: Assumption; measure from the ledger after month 2
A26: Business: top-up and overage revenue, % of plan price | B26: 0.2 | D26: Assumption; voice plans buy top-ups, text plan does not
A27: Business: share of used credits spent on voice | B27: 0.85 | D27: Everyday has no voice by design
A28: Business: monthly churn | B28: 0.05 | D28: Assumption; Indian SMB SaaS benchmarks 3 to 8%
A29: Business: phone numbers included | B29: 1 | D29: Pricing ladder
A30: Growth: price ₹/month | B30: 9999 | D30: As shipped 14 Sept: subscription_plans.py LADDER_SEED
A31: Growth: credits per month | B31: 25000
A32: Growth: share of plan credits actually used | B32: 0.75 | D32: Assumption; measure from the ledger after month 2
A33: Growth: top-up and overage revenue, % of plan price | B33: 0.25 | D33: Assumption; voice plans buy top-ups, text plan does not
A34: Growth: share of used credits spent on voice | B34: 0.9 | D34: Everyday has no voice by design
A35: Growth: monthly churn | B35: 0.03 | D35: Assumption; Indian SMB SaaS benchmarks 3 to 8%
A36: Growth: phone numbers included | B36: 2 | D36: Pricing ladder
A37: Scale: price ₹/month | B37: 19999 | D37: As shipped 14 Sept: subscription_plans.py LADDER_SEED
A38: Scale: credits per month | B38: 60000
A39: Scale: share of plan credits actually used | B39: 0.8 | D39: Assumption; measure from the ledger after month 2
A40: Scale: top-up and overage revenue, % of plan price | B40: 0.3 | D40: Assumption; voice plans buy top-ups, text plan does not
A41: Scale: share of used credits spent on voice | B41: 0.9 | D41: Everyday has no voice by design
A42: Scale: monthly churn | B42: 0.02 | D42: Assumption; Indian SMB SaaS benchmarks 3 to 8%
...

Sheet Plans
A1: Unit economics per plan, per customer per month
A2: All formulas from Assumptions. Gross margin is after provider cost, numbers, third-party SaaS and payment fees.
A4: Line | B4: Everyday | C4: Business | D4: Growth | E4: Scale
A5: Plan price ₹ | B5: =Assumptions!$B$16 | C5: =Assumptions!$B$23 | D5: =Assumptions!$B$30 | E5: =Assumptions!$B$37
A6: Top-up and overage revenue ₹ | B6: =Assumptions!$B$16*Assumptions!$B$19 | C6: =Assumptions!$B$23*Assumptions!$B$26 | D6: =Assumptions!$B$30*Assumptions!$B$33 | E6: =Assumptions!$B$37*Assumptions!$B$40
A7: Revenue per customer ₹ | B7: =B5+B6 | C7: =C5+C6 | D7: =D5+D6 | E7: =E5+E6
A8: Credits used | B8: =Assumptions!$B$17*Assumptions!$B$18*(1+Assumptions!$B$19) | C8: =Assumptions!$B$24*Assumptions!$B$25*(1+Assumptions!$B$26) | D8: =Assumptions!$B$31*Assumptions!$B$32*(1+Assumptions!$B$33) | E8: =Assumptions!$B$38*Assumptions!$B$39*(1+Assumptions!$B$40)
A9: Voice credits used | B9: =B8*Assumptions!$B$20 | C9: =C8*Assumptions!$B$27 | D9: =D8*Assumptions!$B$34 | E9: =E8*Assumptions!$B$41
A10: Text credits used | B10: =B8-B9 | C10: =C8-C9 | D10: =D8-D9 | E10: =E8-E9
A11: Voice minutes | B11: =B9/Assumptions!$B$46 | C11: =C9/Assumptions!$B$46 | D11: =D9/Assumptions!$B$46 | E11: =E9/Assumptions!$B$46
A12: Voice provider cost ₹ | B12: =B11*Assumptions!$B$45 | C12: =C11*Assumptions!$B$45 | D12: =D11*Assumptions!$B$45 | E12: =E11*Assumptions!$B$45
A13: Text provider cost ₹ | B13: =B10*Assumptions!$B$47 | C13: =C10*Assumptions!$B$47 | D13: =D10*Assumptions!$B$47 | E13: =E10*Assumptions!$B$47
A14: Phone numbers cost ₹ | B14: =Assumptions!$B$22*Assumptions!$B$48 | C14: =Assumptions!$B$29*Assumptions!$B$48 | D14: =Assumptions!$B$36*Assumptions!$B$48 | E14: =Assumptions!$B$43*Assumptions!$B$48
A15: Knowledge base cost ₹ | B15: =Assumptions!$B$59*(Assumptions!$B$60+Assumptions!$B$63+Assumptions!$B$62*Assumptions!$B$61)/12 | C15: =Assumptions!$B$59*(Assumptions!$B$60+Assumptions!$B$63+Assumptions!$B$62*Assumptions!$B$61)/12 | D15: =Assumptions!$B$59*(Assumptions!$B$60+Assumptions!$B$63+Assumptions!$B$62*Assumptions!$B$61)/12 | E15: =Assumptions!$B$59*(Assumptions!$B$60+Assumptions!$B$63+Assumptions!$B$62*Assumptions!$B$61)/12
A16: Third-party SaaS ₹ | B16: =Assumptions!$B$50 | C16: =Assumptions!$B$49 | D16: =Assumptions!$B$49 | E16: =Assumptions!$B$49
A17: Payment fee ₹ | B17: =B7*Assumptions!$B$13 | C17: =C7*Assumptions!$B$13 | D17: =D7*Assumptions!$B$13 | E17: =E7*Assumptions!$B$13
A18: Total cost to serve ₹ | B18: =SUM(B12:B17) | C18: =SUM(C12:C17) | D18: =SUM(D12:D17) | E18: =SUM(E12:E17)
A19: Gross profit ₹ | B19: =B7-B18 | C19: =C7-C18 | D19: =D7-D18 | E19: =E7-E18
A20: Gross margin % | B20: =IF(B7=0,0,B19/B7) | C20: =IF(C7=0,0,C19/C7) | D20: =IF(D7=0,0,D19/D7) | E20: =IF(E7=0,0,E19/E7)
A21: Monthly churn | B21: =Assumptions!$B$21 | C21: =Assumptions!$B$28 | D21: =Assumptions!$B$35 | E21: =Assumptions!$B$42
A22: Expected lifetime, months | B22: =IF(B21=0,0,1/B21) | C22: =IF(C21=0,0,1/C21) | D22: =IF(D21=0,0,1/D21) | E22: =IF(E21=0,0,1/E21)
A23: Lifetime gross profit ₹ | B23: =B19*B22 | C23: =C19*C22 | D23: =D19*D22 | E23: =E19*E22
A24: Knowledge pages included | B24: =Assumptions!$B$55 | C24: =Assumptions!$B$56 | D24: =Assumptions!$B$57 | E24: =Assumptions!$B$58
A27: Row references: 5 price, 6 top-up, 7 revenue, 8 credits used, 9 voice credits, 10 text credits, 11 minutes, 12 voice cost, 13 text cost, 14 numbers, 15 KB, 16 SaaS, 17 fee, 18 total cost, 19 gross profit

Sheet Model
A1: Monthly model, 24 months
A2: Customers by plan, revenue, cost to serve, infrastructure that steps with call minutes, acquisition, payroll, EBITDA, cash and breakeven.
A4: Line | B4: M1 | C4: M2 | D4: M3 | E4: M4 | F4: M5 | G4: M6 | H4: M7 | I4: M8 | J4: M9 | K4: M10 | L4: M11 | M4: M12 | N4: M13 | O4: M14 | P4: M15 | Q4: M16 | R4: M17 | S4: M18 | T4: M19 | U4: M20 | V4: M21 | W4: M22 | X4: M23 | Y4: M24
A5: Month number | B5: 1 | C5: 2 | D5: 3 | E5: 4 | F5: 5 | G5: 6 | H5: 7 | I5: 8 | J5: 9 | K5: 10 | L5: 11 | M5: 12 | N5: 13 | O5: 14 | P5: 15 | Q5: 16 | R5: 17 | S5: 18 | T5: 19 | U5: 20 | V5: 21 | W5: 22 | X5: 23 | Y5: 24
A6: Ads budget ₹ | B6: =IF(B5<=6,Assumptions!$B$73,IF(B5<=12,Assumptions!$B$74,Assumptions!$B$75)) | C6: =IF(C5<=6,Assumptions!$B$73,IF(C5<=12,Assumptions!$B$74,Assumptions!$B$75)) | D6: =IF(D5<=6,Assumptions!$B$73,IF(D5<=12,Assumptions!$B$74,Assumptions!$B$75)) | E6: =IF(E5<=6,Assumptions!$B$73,IF(E5<=12,Assumptions!$B$74,Assumptions!$B$75)) | F6: =IF(F5<=6,Assumptions!$B$73,IF(F5<=12,Assumptions!$B$74,Assumptions!$B$75)) | G6: =IF(G5<=6,Assumptions!$B$73,IF(G5<=12,Assumptions!$B$74,Assumptions!$B$75)) | H6: =IF(H5<=6,Assumptions!$B$73,IF(H5<=12,Assumptions!$B$74,Assumptions!$B$75)) | I6: =IF(I5<=6,Assumptions!$B$73,IF(I5<=12,Assumptions!$B$74,Assumptions!$B$75)) | ... Y6: =IF(Y5<=6,Assumptions!$B$73,IF(Y5<=12,Assumptions!$B$74,Assumptions!$B$75))
A7: Free signups from ads | B7: =IF(Assumptions!$B$67=0,0,B6/Assumptions!$B$67) | C7: =IF(Assumptions!$B$67=0,0,C6/Assumptions!$B$67) | D7: =IF(Assumptions!$B$67=0,0,D6/Assumptions!$B$67) | E7: =IF(Assumptions!$B$67=0,0,E6/Assumptions!$B$67) | F7: =IF(Assumptions!$B$67=0,0,F6/Assumptions!$B$67) | G7: =IF(Assumptions!$B$67=0,0,G6/Assumptions!$B$67) | H7: =IF(Assumptions!$B$67=0,0,H6/Assumptions!$B$67) | I7: =IF(Assumptions!$B$67=0,0,I6/Assumptions!$B$67) | ... Y7: =IF(Assumptions!$B$67=0,0,Y6/Assumptions!$B$67)
A8: Organic free signups | B8: =Assumptions!$B$76+Assumptions!$B$77*(B5-1) | C8: =Assumptions!$B$76+Assumptions!$B$77*(C5-1) | D8: =Assumptions!$B$76+Assumptions!$B$77*(D5-1) | E8: =Assumptions!$B$76+Assumptions!$B$77*(E5-1) | F8: =Assumptions!$B$76+Assumptions!$B$77*(F5-1) | G8: =Assumptions!$B$76+Assumptions!$B$77*(G5-1) | H8: =Assumptions!$B$76+Assumptions!$B$77*(H5-1) | I8: =Assumptions!$B$76+Assumptions!$B$77*(I5-1) | ... Y8: =Assumptions!$B$76+Assumptions!$B$77*(Y5-1)
A9: Total free signups | B9: =B7+B8 | C9: =C7+C8 | D9: =D7+D8 | E9: =E7+E8 | F9: =F7+F8 | G9: =G7+G8 | H9: =H7+H8 | I9: =I7+I8 | ... Y9: =Y7+Y8
A10: New paid customers from self-serve | B10: =B9*Assumptions!$B$68 | C10: =C9*Assumptions!$B$68 | D10: =D9*Assumptions!$B$68 | E10: =E9*Assumptions!$B$68 | F10: =F9*Assumptions!$B$68 | G10: =G9*Assumptions!$B$68 | H10: =H9*Assumptions!$B$68 | I10: =I9*Assumptions!$B$68 | ... Y10: =Y9*Assumptions!$B$68
A11: New Everyday | B11: =B10*Assumptions!$B$69 | C11: =C10*Assumptions!$B$69 | D11: =D10*Assumptions!$B$69 | E11: =E10*Assumptions!$B$69 | F11: =F10*Assumptions!$B$69 | G11: =G10*Assumptions!$B$69 | H11: =H10*Assumptions!$B$69 | I11: =I10*Assumptions!$B$69 | ... Y11: =Y10*Assumptions!$B$69
A12: New Business | B12: =B10*Assumptions!$B$70 | C12: =C10*Assumptions!$B$70 | D12: =D10*Assumptions!$B$70 | E12: =E10*Assumptions!$B$70 | F12: =F10*Assumptions!$B$70 | G12: =G10*Assumptions!$B$70 | H12: =H10*Assumptions!$B$70 | I12: =I10*Assumptions!$B$70 | ... Y12: =Y10*Assumptions!$B$70
A13: New Growth | B13: =B10*Assumptions!$B$71 | C13: =C10*Assumptions!$B$71 | D13: =D10*Assumptions!$B$71 | E13: =E10*Assumptions!$B$71 | F13: =F10*Assumptions!$B$71 | G13: =G10*Assumptions!$B$71 | H13: =H10*Assumptions!$B$71 | I13: =I10*Assumptions!$B$71 | ... Y13: =Y10*Assumptions!$B$71
A14: New Scale | B14: =B10*Assumptions!$B$72 | C14: =C10*Assumptions!$B$72 | D14: =D10*Assumptions!$B$72 | E14: =E10*Assumptions!$B$72 | F14: =F10*Assumptions!$B$72 | G14: =G10*Assumptions!$B$72 | H14: =H10*Assumptions!$B$72 | I14: =I10*Assumptions!$B$72 | ... Y14: =Y10*Assumptions!$B$72
A15: New Business via champions | B15: =IF(B5>=Assumptions!$B$78,Assumptions!$B$79*Assumptions!$B$80,0) | C15: =IF(C5>=Assumptions!$B$78,Assumptions!$B$79*Assumptions!$B$80,0) | D15: =IF(D5>=Assumptions!$B$78,Assumptions!$B$79*Assumptions!$B$80,0) | E15: =IF(E5>=Assumptions!$B$78,Assumptions!$B$79*Assumptions!$B$80,0) | F15: =IF(F5>=Assumptions!$B$78,Assumptions!$B$79*Assumptions!$B$80,0) | G15: =IF(G5>=Assumptions!$B$78,Assumptions!$B$79*Assumptions!$B$80,0) | H15: =IF(H5>=Assumptions!$B$78,Assumptions!$B$79*Assumptions!$B$80,0) | I15: =IF(I5>=Assumptions!$B$78,Assumptions!$B$79*Assumptions!$B$80,0) | ... Y15: =IF(Y5>=Assumptions!$B$78,Assumptions!$B$79*Assumptions!$B$80,0)
A16: Customers: Everyday | B16: =0*(1-Assumptions!$B$21)+B11 | C16: =B16*(1-Assumptions!$B$21)+C11 | D16: =C16*(1-Assumptions!$B$21)+D11 | E16: =D16*(1-Assumptions!$B$21)+E11 | F16: =E16*(1-Assumptions!$B$21)+F11 | G16: =F16*(1-Assumptions!$B$21)+G11 | H16: =G16*(1-Assumptions!$B$21)+H11 | I16: =H16*(1-Assumptions!$B$21)+I11 | J16: =I16*(1-Assumptions!$B$21)+J11 | ... Y16: =X16*(1-Assumptions!$B$21)+Y11
A17: Customers: Business | B17: =0*(1-Assumptions!$B$28)+B12 | C17: =B17*(1-Assumptions!$B$28)+C12 | D17: =C17*(1-Assumptions!$B$28)+D12 | E17: =D17*(1-Assumptions!$B$28)+E12 | F17: =E17*(1-Assumptions!$B$28)+F12 | G17: =F17*(1-Assumptions!$B$28)+G12 | H17: =G17*(1-Assumptions!$B$28)+H12 | I17: =H17*(1-Assumptions!$B$28)+I12 | J17: =I17*(1-Assumptions!$B$28)+J12 | ... Y17: =X17*(1-Assumptions!$B$28)+Y12
A18: Customers: Growth | B18: =0*(1-Assumptions!$B$35)+B13 | C18: =B18*(1-Assumptions!$B$35)+C13 | D18: =C18*(1-Assumptions!$B$35)+D13 | E18: =D18*(1-Assumptions!$B$35)+E13 | F18: =E18*(1-Assumptions!$B$35)+F13 | G18: =F18*(1-Assumptions!$B$35)+G13 | H18: =G18*(1-Assumptions!$B$35)+H13 | I18: =H18*(1-Assumptions!$B$35)+I13 | J18: =I18*(1-Assumptions!$B$35)+J13 | ... Y18: =X18*(1-Assumptions!$B$35)+Y13
A19: Customers: Scale | B19: =0*(1-Assumptions!$B$42)+B14 | C19: =B19*(1-Assumptions!$B$42)+C14 | D19: =C19*(1-Assumptions!$B$42)+D14 | E19: =D19*(1-Assumptions!$B$42)+E14 | F19: =E19*(1-Assumptions!$B$42)+F14 | G19: =F19*(1-Assumptions!$B$42)+G14 | H19: =G19*(1-Assumptions!$B$42)+H14 | I19: =H19*(1-Assumptions!$B$42)+I14 | J19: =I19*(1-Assumptions!$B$42)+J14 | ... Y19: =X19*(1-Assumptions!$B$42)+Y14
A20: Customers: Business (champion-sourced) | B20: =0*(1-Assumptions!$B$28)+B15 | C20: =B20*(1-Assumptions!$B$28)+C15 | D20: =C20*(1-Assumptions!$B$28)+D15 | E20: =D20*(1-Assumptions!$B$28)+E15 | F20: =E20*(1-Assumptions!$B$28)+F15 | G20: =F20*(1-Assumptions!$B$28)+G15 | H20: =G20*(1-Assumptions!$B$28)+H15 | I20: =H20*(1-Assumptions!$B$28)+I15 | J20: =I20*(1-Assumptions!$B$28)+J15 | ... Y20: =X20*(1-Assumptions!$B$28)+Y15
A21: Paying customers, total | B21: =SUM(B16:B20) | C21: =SUM(C16:C20) | D21: =SUM(D16:D20) | E21: =SUM(E16:E20) | F21: =SUM(F16:F20) | G21: =SUM(G16:G20) | H21: =SUM(H16:H20) | I21: =SUM(I16:I20) | ... Y21: =SUM(Y16:Y20)
A22: Revenue: Everyday ₹ | B22: =B16*Plans!$B$7 | C22: =C16*Plans!$B$7 | D22: =D16*Plans!$B$7 | E22: =E16*Plans!$B$7 | F22: =F16*Plans!$B$7 | G22: =G16*Plans!$B$7 | H22: =H16*Plans!$B$7 | I22: =I16*Plans!$B$7 | ... Y22: =Y16*Plans!$B$7
A23: Revenue: Business ₹ | B23: =B17*Plans!$C$7 | C23: =C17*Plans!$C$7 | D23: =D17*Plans!$C$7 | E23: =E17*Plans!$C$7 | F23: =F17*Plans!$C$7 | G23: =G17*Plans!$C$7 | H23: =H17*Plans!$C$7 | I23: =I17*Plans!$C$7 | ... Y23: =Y17*Plans!$C$7
A24: Revenue: Growth ₹ | B24: =B18*Plans!$D$7 | C24: =C18*Plans!$D$7 | D24: =D18*Plans!$D$7 | E24: =E18*Plans!$D$7 | F24: =F18*Plans!$D$7 | G24: =G18*Plans!$D$7 | H24: =H18*Plans!$D$7 | I24: =I18*Plans!$D$7 | ... Y24: =Y18*Plans!$D$7
A25: Revenue: Scale ₹ | B25: =B19*Plans!$E$7 | C25: =C19*Plans!$E$7 | D25: =D19*Plans!$E$7 | E25: =E19*Plans!$E$7 | F25: =F19*Plans!$E$7 | G25: =G19*Plans!$E$7 | H25: =H19*Plans!$E$7 | I25: =I19*Plans!$E$7 | ... Y25: =Y19*Plans!$E$7
A26: Revenue: champion accounts ₹ | B26: =B20*Plans!$C$7 | C26: =C20*Plans!$C$7 | D26: =D20*Plans!$C$7 | E26: =E20*Plans!$C$7 | F26: =F20*Plans!$C$7 | G26: =G20*Plans!$C$7 | H26: =H20*Plans!$C$7 | I26: =I20*Plans!$C$7 | ... Y26: =Y20*Plans!$C$7
A27: REVENUE ₹ | B27: =SUM(B22:B26) | C27: =SUM(C22:C26) | D27: =SUM(D22:D26) | E27: =SUM(E22:E26) | F27: =SUM(F22:F26) | G27: =SUM(G22:G26) | H27: =SUM(H22:H26) | I27: =SUM(I22:I26) | ... Y27: =SUM(Y22:Y26)
A28: Cost to serve: Everyday ₹ | B28: =B16*Plans!$B$18 | C28: =C16*Plans!$B$18 | D28: =D16*Plans!$B$18 | E28: =E16*Plans!$B$18 | F28: =F16*Plans!$B$18 | G28: =G16*Plans!$B$18 | H28: =H16*Plans!$B$18 | I28: =I16*Plans!$B$18 | ... Y28: =Y16*Plans!$B$18
A29: Cost to serve: Business ₹ | B29: =B17*Plans!$C$18 | C29: =C17*Plans!$C$18 | D29: =D17*Plans!$C$18 | E29: =E17*Plans!$C$18 | F29: =F17*Plans!$C$18 | G29: =G17*Plans!$C$18 | H29: =H17*Plans!$C$18 | I29: =I17*Plans!$C$18 | ... Y29: =Y17*Plans!$C$18
A30: Cost to serve: Growth ₹ | B30: =B18*Plans!$D$18 | C30: =C18*Plans!$D$18 | D30: =D18*Plans!$D$18 | E30: =E18*Plans!$D$18 | F30: =F18*Plans!$D$18 | G30: =G18*Plans!$D$18 | H30: =H18*Plans!$D$18 | I30: =I18*Plans!$D$18 | ... Y30: =Y18*Plans!$D$18
A31: Cost to serve: Scale ₹ | B31: =B19*Plans!$E$18 | C31: =C19*Plans!$E$18 | D31: =D19*Plans!$E$18 | E31: =E19*Plans!$E$18 | F31: =F19*Plans!$E$18 | G31: =G19*Plans!$E$18 | H31: =H19*Plans!$E$18 | I31: =I19*Plans!$E$18 | ... Y31: =Y19*Plans!$E$18
A32: Cost to serve: champion accounts ₹ | B32: =B20*Plans!$C$18 | C32: =C20*Plans!$C$18 | D32: =D20*Plans!$C$18 | E32: =E20*Plans!$C$18 | F32: =F20*Plans!$C$18 | G32: =G20*Plans!$C$18 | H32: =H20*Plans!$C$18 | I32: =I20*Plans!$C$18 | ... Y32: =Y20*Plans!$C$18
A33: Cost to serve before Sarvam credit ₹ | B33: =SUM(B28:B32) | C33: =SUM(C28:C32) | D33: =SUM(D28:D32) | E33: =SUM(E28:E32) | F33: =SUM(F28:F32) | G33: =SUM(G28:G32) | H33: =SUM(H28:H32) | I33: =SUM(I28:I32) | ... Y33: =SUM(Y28:Y32)
A34: Sarvam free credit applied ₹ | B34: =IF(B5<=Assumptions!$B$52,MIN(Assumptions!$B$51,(B17*Plans!$C$12+B18*Plans!$D$12+B19*Plans!$E$12+B20*Plans!$C$12)*Assumptions!$B$53),0) | C34: =IF(C5<=Assumptions!$B$52,MIN(Assumptions!$B$51,(C17*Plans!$C$12+C18*Plans!$D$12+C19*Plans!$E$12+C20*Plans!$C$12)*Assumptions!$B$53),0) | D34: =IF(D5<=Assumptions!$B$52,MIN(Assumptions!$B$51,(D17*Plans!$C$12+D18*Plans!$D$12+D19*Plans!$E$12+D20*Plans!$C$12)*Assumptions!$B$53),0) | E34: =IF(E5<=Assumptions!$B$52,MIN(Assumptions!$B$51,(E17*Plans!$C$12+E18*Plans!$D$12+E19*Plans!$E$12+E20*Plans!$C$12)*Assumptions!$B$53),0) | F34: =IF(F5<=Assumptions!$B$52,MIN(Assumptions!$B$51,(F17*Plans!$C$12+F18*Plans!$D$12+F19*Plans!$E$12+F20*Plans!$C$12)*Assumptions!$B$53),0) | G34: =IF(G5<=Assumptions!$B$52,MIN(Assumptions!$B$51,(G17*Plans!$C$12+G18*Plans!$D$12+G19*Plans!$E$12+G20*Plans!$C$12)*Assumptions!$B$53),0) | H34: =IF(H5<=Assumptions!$B$52,MIN(Assumptions!$B$51,(H17*Plans!$C$12+H18*Plans!$D$12+H19*Plans!$E$12+H20*Plans!$C$12)*Assumptions!$B$53),0) | I34: =IF(I5<=Assumptions!$B$52,MIN(Assumptions!$B$51,(I17*Plans!$C$12+I18*Plans!$D$12+I19*Plans!$E$12+I20*Plans!$C$12)*Assumptions!$B$53),0) | ... Y34: =IF(Y5<=Assumptions!$B$52,MIN(Assumptions!$B$51,(Y17*Plans!$C$12+Y18*Plans!$D$12+Y19*Plans!$E$12+Y20*Plans!$C$12)*Assumptions!$B$53),0)
A35: COST TO SERVE ₹ | B35: =B33-B34 | C35: =C33-C34 | D35: =D33-D34 | E35: =E33-E34 | F35: =F33-F34 | G35: =G33-G34 | H35: =H33-H34 | I35: =I33-I34 | ... Y35: =Y33-Y34
A36: GROSS PROFIT ₹ | B36: =B27-B35 | C36: =C27-C35 | D36: =D27-D35 | E36: =E27-E35 | F36: =F27-F35 | G36: =G27-G35 | H36: =H27-H35 | I36: =I27-I35 | ... Y36: =Y27-Y35
A37: Gross margin % | B37: =IF(B27=0,0,B36/B27) | C37: =IF(C27=0,0,C36/C27) | D37: =IF(D27=0,0,D36/D27) | E37: =IF(E27=0,0,E36/E27) | F37: =IF(F27=0,0,F36/F27) | G37: =IF(G27=0,0,G36/G27) | H37: =IF(H27=0,0,H36/H27) | I37: =IF(I27=0,0,I36/I27) | ... Y37: =IF(Y27=0,0,Y36/Y27)
A38: Voice minutes this month | B38: =B17*Plans!$C$11+B18*Plans!$D$11+B19*Plans!$E$11+B20*Plans!$C$11 | C38: =C17*Plans!$C$11+C18*Plans!$D$11+C19*Plans!$E$11+C20*Plans!$C$11 | D38: =D17*Plans!$C$11+D18*Plans!$D$11+D19*Plans!$E$11+D20*Plans!$C$11 | E38: =E17*Plans!$C$11+E18*Plans!$D$11+E19*Plans!$E$11+E20*Plans!$C$11 | F38: =F17*Plans!$C$11+F18*Plans!$D$11+F19*Plans!$E$11+F20*Plans!$C$11 | G38: =G17*Plans!$C$11+G18*Plans!$D$11+G19*Plans!$E$11+G20*Plans!$C$11 | H38: =H17*Plans!$C$11+H18*Plans!$D$11+H19*Plans!$E$11+H20*Plans!$C$11 | I38: =I17*Plans!$C$11+I18*Plans!$D$11+I19*Plans!$E$11+I20*Plans!$C$11 | ... Y38: =Y17*Plans!$C$11+Y18*Plans!$D$11+Y19*Plans!$E$11+Y20*Plans!$C$11
A39: Infrastructure ₹ (auto-scaled by minutes) | B39: =IF(B38<=Assumptions!$B$88,Assumptions!$B$84,IF(B38<=Assumptions!$B$89,Assumptions!$B$85,IF(B38<=Assumptions!$B$90,Assumptions!$B$86,Assumptions!$B$86+Assumptions!$B$87*(B38-Assumptions!$B$90)/1000000))) | C39: =IF(C38<=Assumptions!$B$88,Assumptions!$B$84,IF(C38<=Assumptions!$B$89,Assumptions!$B$85,IF(C38<=Assumptions!$B$90,Assumptions!$B$86,Assumptions!$B$86+Assumptions!$B$87*(C38-Assumptions!$B$90)/1000000))) | D39: =IF(D38<=Assumptions!$B$88,Assumptions!$B$84,IF(D38<=Assumptions!$B$89,Assumptions!$B$85,IF(D38<=Assumptions!$B$90,Assumptions!$B$86,Assumptions!$B$86+Assumptions!$B$87*(D38-Assumptions!$B$90)/1000000))) | E39: =IF(E38<=Assumptions!$B$88,Assumptions!$B$84,IF(E38<=Assumptions!$B$89,Assumptions!$B$85,IF(E38<=Assumptions!$B$90,Assumptions!$B$86,Assumptions!$B$86+Assumptions!$B$87*(E38-Assumptions!$B$90)/1000000))) | F39: =IF(F38<=Assumptions!$B$88,Assumptions!$B$84,IF(F38<=Assumptions!$B$89,Assumptions!$B$85,IF(F38<=Assumptions!$B$90,Assumptions!$B$86,Assumptions!$B$86+Assumptions!$B$87*(F38-Assumptions!$B$90)/1000000))) | G39: =IF(G38<=Assumptions!$B$88,Assumptions!$B$84,IF(G38<=Assumptions!$B$89,Assumptions!$B$85,IF(G38<=Assumptions!$B$90,Assumptions!$B$86,Assumptions!$B$86+Assumptions!$B$87*(G38-Assumptions!$B$90)/1000000))) | H39: =IF(H38<=Assumptions!$B$88,Assumptions!$B$84,IF(H38<=Assumptions!$B$89,Assumptions!$B$85,IF(H38<=Assumptions!$B$90,Assumptions!$B$86,Assumptions!$B$86+Assumptions!$B$87*(H38-Assumptions!$B$90)/1000000))) | I39: =IF(I38<=Assumptions!$B$88,Assumptions!$B$84,IF(I38<=Assumptions!$B$89,Assumptions!$B$85,IF(I38<=Assumptions!$B$90,Assumptions!$B$86,Assumptions!$B$86+Assumptions!$B$87*(I38-Assumptions!$B$90)/1000000))) | ... Y39: =IF(Y38<=Assumptions!$B$88,Assumptions!$B$84,IF(Y38<=Assumptions!$B$89,Assumptions!$B$85,IF(Y38<=Assumptions!$B$90,Assumptions!$B$86,Assumptions!$B$86+Assumptions!$B$87*(Y38-Assumptions!$B$90)/1000000)))
A40: Fixed SaaS ₹ | B40: =IF(B38<=Assumptions!$B$88,Assumptions!$B$91,Assumptions!$B$92) | C40: =IF(C38<=Assumptions!$B$88,Assumptions!$B$91,Assumptions!$B$92) | D40: =IF(D38<=Assumptions!$B$88,Assumptions!$B$91,Assumptions!$B$92) | E40: =IF(E38<=Assumptions!$B$88,Assumptions!$B$91,Assumptions!$B$92) | F40: =IF(F38<=Assumptions!$B$88,Assumptions!$B$91,Assumptions!$B$92) | G40: =IF(G38<=Assumptions!$B$88,Assumptions!$B$91,Assumptions!$B$92) | H40: =IF(H38<=Assumptions!$B$88,Assumptions!$B$91,Assumptions!$B$92) | I40: =IF(I38<=Assumptions!$B$88,Assumptions!$B$91,Assumptions!$B$92) | ... Y40: =IF(Y38<=Assumptions!$B$88,Assumptions!$B$91,Assumptions!$B$92)
A41: Payroll ₹ | B41: =IF(B5<=6,Assumptions!$B$94,IF(B5<=12,Assumptions!$B$95,Assumptions!$B$96)) | C41: =IF(C5<=6,Assumptions!$B$94,IF(C5<=12,Assumptions!$B$95,Assumptions!$B$96)) | D41: =IF(D5<=6,Assumptions!$B$94,IF(D5<=12,Assumptions!$B$95,Assumptions!$B$96)) | E41: =IF(E5<=6,Assumptions!$B$94,IF(E5<=12,Assumptions!$B$95,Assumptions!$B$96)) | F41: =IF(F5<=6,Assumptions!$B$94,IF(F5<=12,Assumptions!$B$95,Assumptions!$B$96)) | G41: =IF(G5<=6,Assumptions!$B$94,IF(G5<=12,Assumptions!$B$95,Assumptions!$B$96)) | H41: =IF(H5<=6,Assumptions!$B$94,IF(H5<=12,Assumptions!$B$95,Assumptions!$B$96)) | I41: =IF(I5<=6,Assumptions!$B$94,IF(I5<=12,Assumptions!$B$95,Assumptions!$B$96)) | ... Y41: =IF(Y5<=6,Assumptions!$B$94,IF(Y5<=12,Assumptions!$B$95,Assumptions!$B$96))
...

Sheet BalanceSheet
A1: Balance sheet snapshot, end of each month
A2: Simplified: prepaid SaaS has no receivables; unused prepaid credits are a liability (deferred revenue). No debt, no fixed assets, no tax.
A4: Line | B4: M1 | C4: M2 | D4: M3 | E4: M4 | F4: M5 | G4: M6 | H4: M7 | I4: M8 | J4: M9 | K4: M10 | L4: M11 | M4: M12 | N4: M13 | O4: M14 | P4: M15 | Q4: M16 | R4: M17 | S4: M18 | T4: M19 | U4: M20 | V4: M21 | W4: M22 | X4: M23 | Y4: M24
A5: Cash ₹ | B5: =Model!B47 | C5: =Model!C47 | D5: =Model!D47 | E5: =Model!E47 | F5: =Model!F47 | G5: =Model!G47 | H5: =Model!H47 | I5: =Model!I47 | ... Y5: =Model!Y47
A6: Total assets ₹ | B6: =B5 | C6: =C5 | D6: =D5 | E6: =E5 | F6: =F5 | G6: =G5 | H6: =H5 | I6: =I5 | ... Y6: =Y5
A7: Deferred revenue: unused prepaid credits ₹ | B7: =Model!B16*Assumptions!$B$16*(1-Assumptions!$B$18)+Model!B17*Assumptions!$B$23*(1-Assumptions!$B$25)+Model!B18*Assumptions!$B$30*(1-Assumptions!$B$32)+Model!B19*Assumptions!$B$37*(1-Assumptions!$B$39)+Model!B20*Assumptions!$B$23*(1-Assumptions!$B$25) | C7: =Model!C16*Assumptions!$B$16*(1-Assumptions!$B$18)+Model!C17*Assumptions!$B$23*(1-Assumptions!$B$25)+Model!C18*Assumptions!$B$30*(1-Assumptions!$B$32)+Model!C19*Assumptions!$B$37*(1-Assumptions!$B$39)+Model!C20*Assumptions!$B$23*(1-Assumptions!$B$25) | D7: =Model!D16*Assumptions!$B$16*(1-Assumptions!$B$18)+Model!D17*Assumptions!$B$23*(1-Assumptions!$B$25)+Model!D18*Assumptions!$B$30*(1-Assumptions!$B$32)+Model!D19*Assumptions!$B$37*(1-Assumptions!$B$39)+Model!D20*Assumptions!$B$23*(1-Assumptions!$B$25) | E7: =Model!E16*Assumptions!$B$16*(1-Assumptions!$B$18)+Model!E17*Assumptions!$B$23*(1-Assumptions!$B$25)+Model!E18*Assumptions!$B$30*(1-Assumptions!$B$32)+Model!E19*Assumptions!$B$37*(1-Assumptions!$B$39)+Model!E20*Assumptions!$B$23*(1-Assumptions!$B$25) | F7: =Model!F16*Assumptions!$B$16*(1-Assumptions!$B$18)+Model!F17*Assumptions!$B$23*(1-Assumptions!$B$25)+Model!F18*Assumptions!$B$30*(1-Assumptions!$B$32)+Model!F19*Assumptions!$B$37*(1-Assumptions!$B$39)+Model!F20*Assumptions!$B$23*(1-Assumptions!$B$25) | G7: =Model!G16*Assumptions!$B$16*(1-Assumptions!$B$18)+Model!G17*Assumptions!$B$23*(1-Assumptions!$B$25)+Model!G18*Assumptions!$B$30*(1-Assumptions!$B$32)+Model!G19*Assumptions!$B$37*(1-Assumptions!$B$39)+Model!G20*Assumptions!$B$23*(1-Assumptions!$B$25) | H7: =Model!H16*Assumptions!$B$16*(1-Assumptions!$B$18)+Model!H17*Assumptions!$B$23*(1-Assumptions!$B$25)+Model!H18*Assumptions!$B$30*(1-Assumptions!$B$32)+Model!H19*Assumptions!$B$37*(1-Assumptions!$B$39)+Model!H20*Assumptions!$B$23*(1-Assumptions!$B$25) | I7: =Model!I16*Assumptions!$B$16*(1-Assumptions!$B$18)+Model!I17*Assumptions!$B$23*(1-Assumptions!$B$25)+Model!I18*Assumptions!$B$30*(1-Assumptions!$B$32)+Model!I19*Assumptions!$B$37*(1-Assumptions!$B$39)+Model!I20*Assumptions!$B$23*(1-Assumptions!$B$25) | ... Y7: =Model!Y16*Assumptions!$B$16*(1-Assumptions!$B$18)+Model!Y17*Assumptions!$B$23*(1-Assumptions!$B$25)+Model!Y18*Assumptions!$B$30*(1-Assumptions!$B$32)+Model!Y19*Assumptions!$B$37*(1-Assumptions!$B$39)+Model!Y20*Assumptions!$B$23*(1-Assumptions!$B$25)
A8: Total liabilities ₹ | B8: =B7 | C8: =C7 | D8: =D7 | E8: =E7 | F8: =F7 | G8: =G7 | H8: =H7 | I8: =I7 | ... Y8: =Y7
A9: Equity (assets less liabilities) ₹ | B9: =B6-B8 | C9: =C6-C8 | D9: =D6-D8 | E9: =E6-E8 | F9: =F6-F8 | G9: =G6-G8 | H9: =H6-H8 | I9: =I6-I8 | ... Y9: =Y6-Y8
A10: Runway at this month's burn, months | B10: =IF(Model!B46>=0,"profitable",IF(B5<=0,0,B5/-Model!B46)) | C10: =IF(Model!C46>=0,"profitable",IF(C5<=0,0,C5/-Model!C46)) | D10: =IF(Model!D46>=0,"profitable",IF(D5<=0,0,D5/-Model!D46)) | E10: =IF(Model!E46>=0,"profitable",IF(E5<=0,0,E5/-Model!E46)) | F10: =IF(Model!F46>=0,"profitable",IF(F5<=0,0,F5/-Model!F46)) | G10: =IF(Model!G46>=0,"profitable",IF(G5<=0,0,G5/-Model!G46)) | H10: =IF(Model!H46>=0,"profitable",IF(H5<=0,0,H5/-Model!H46)) | I10: =IF(Model!I46>=0,"profitable",IF(I5<=0,0,I5/-Model!I46)) | ... Y10: =IF(Model!Y46>=0,"profitable",IF(Y5<=0,0,Y5/-Model!Y46))

Sheet Knowledge
A1: Knowledge base caps, embedding cost and what we charge
A2: Embeddings run on our own CPU (bge-m3), so the cost is compute and storage, not a vendor fee. Scanned pages go through Sarvam OCR.
A4: Line | B4: Everyday | C4: Business | D4: Growth | E4: Scale
A5: Pages included | B5: =Assumptions!$B$55 | C5: =Assumptions!$B$56 | D5: =Assumptions!$B$57 | E5: =Assumptions!$B$58
A6: Cost to us of the included pages ₹ (one-time) | B6: =B5*(Assumptions!$B$60+Assumptions!$B$62*Assumptions!$B$61) | C6: =C5*(Assumptions!$B$60+Assumptions!$B$62*Assumptions!$B$61) | D6: =D5*(Assumptions!$B$60+Assumptions!$B$62*Assumptions!$B$61) | E6: =E5*(Assumptions!$B$60+Assumptions!$B$62*Assumptions!$B$61)
A7: Storage of included pages ₹/month | B7: =B5*Assumptions!$B$63 | C7: =C5*Assumptions!$B$63 | D7: =D5*Assumptions!$B$63 | E7: =E5*Assumptions!$B$63
A8: Credits charged per 10 typed pages over cap | B8: =Assumptions!$B$64 | C8: =Assumptions!$B$64 | D8: =Assumptions!$B$64 | E8: =Assumptions!$B$64
A9: Credits charged per scanned page over cap | B9: =Assumptions!$B$65 | C9: =Assumptions!$B$65 | D9: =Assumptions!$B$65 | E9: =Assumptions!$B$65
A10: Our cost per scanned page over cap ₹ | B10: =Assumptions!$B$61+Assumptions!$B$60 | C10: =Assumptions!$B$61+Assumptions!$B$60 | D10: =Assumptions!$B$61+Assumptions!$B$60 | E10: =Assumptions!$B$61+Assumptions!$B$60
A11: Our cost per 10 typed pages over cap ₹ | B11: =10*Assumptions!$B$60 | C11: =10*Assumptions!$B$60 | D11: =10*Assumptions!$B$60 | E11: =10*Assumptions!$B$60
A12: Margin per scanned page over cap ₹ | B12: =B9*Assumptions!$B$11-B10 | C12: =C9*Assumptions!$B$11-C10 | D12: =D9*Assumptions!$B$11-D10 | E12: =E9*Assumptions!$B$11-E10
A13: Margin per 10 typed pages over cap ₹ | B13: =B8*Assumptions!$B$11-B11 | C13: =C8*Assumptions!$B$11-C11 | D13: =D8*Assumptions!$B$11-D11 | E13: =E8*Assumptions!$B$11-E11
A15: Notes
A16: Query-time embedding is inside the 2-credit knowledge answer. Re-embedding on a model change is free. Free plan: 50 pages, no OCR.
